2023-02-27 04:43:12,056 DEBUG    root            Loaded Command Group: ['gcloud', 'auth']
2023-02-27 04:43:12,120 DEBUG    root            Loaded Command Group: ['gcloud', 'config']
2023-02-27 04:43:12,135 DEBUG    root            Loaded Command Group: ['gcloud', 'auth', 'list']
2023-02-27 04:43:12,140 DEBUG    root            Running [gcloud.auth.list] with arguments: [--filter: "status=ACTIVE", --format: "value(account)", --quiet: "True", --verbosity: "warning"]
2023-02-27 04:43:12,141 DEBUG    root            Loaded Command Group: ['gcloud', 'config', 'get_value']
2023-02-27 04:43:12,144 DEBUG    root            Running [gcloud.config.get-value] with arguments: [--format: "json", SECTION/PROPERTY: "project"]
2023-02-27 04:43:13,468 DEBUG    root            Chosen display Format:value(.) json
2023-02-27 04:43:13,470 INFO     root            Display format: "value(.) json"
2023-02-27 04:43:13,471 INFO     ___FILE_ONLY___ "terrafrom-test-368523"
2023-02-27 04:43:13,472 DEBUG    root            Chosen display Format:    table[title='Credentialed Accounts'](
        status.yesno(yes='*', no=''):label=ACTIVE,
        account
    ) value(account)
2023-02-27 04:43:13,472 INFO     ___FILE_ONLY___ 

2023-02-27 04:43:13,473 INFO     root            Display format: "    table[title='Credentialed Accounts'](
        status.yesno(yes='*', no=''):label=ACTIVE,
        account
    ) value(account)"
2023-02-27 04:43:13,474 DEBUG    root            Checking for updates...
2023-02-27 04:43:13,475 INFO     ___FILE_ONLY___ neelamshashidhar07@gmail.com

2023-02-27 04:43:13,477 DEBUG    root            Checking for updates...
2023-02-27 04:43:14,641 DEBUG    urllib3.connectionpool Starting new HTTPS connection (1): dl.google.com:443
2023-02-27 04:43:14,641 DEBUG    urllib3.connectionpool Starting new HTTPS connection (1): dl.google.com:443
2023-02-27 06:43:20,880 DEBUG    root            Failed to perform update check.
Traceback (most recent call last):
  File "/Users/shashidharreddyneelam/Library/Application Support/cloud-code/installer/google-cloud-sdk/lib/third_party/urllib3/connectionpool.py", line 703, in urlopen
    httplib_response = self._make_request(
                       ^^^^^^^^^^^^^^^^^^^
  File "/Users/shashidharreddyneelam/Library/Application Support/cloud-code/installer/google-cloud-sdk/lib/third_party/urllib3/connectionpool.py", line 386, in _make_request
    self._validate_conn(conn)
  File "/Users/shashidharreddyneelam/Library/Application Support/cloud-code/installer/google-cloud-sdk/lib/third_party/urllib3/connectionpool.py", line 1040, in _validate_conn
    conn.connect()
  File "/Users/shashidharreddyneelam/Library/Application Support/cloud-code/installer/google-cloud-sdk/lib/third_party/urllib3/connection.py", line 414, in connect
    self.sock = ssl_wrap_socket(
                ^^^^^^^^^^^^^^^^
  File "/Users/shashidharreddyneelam/Library/Application Support/cloud-code/installer/google-cloud-sdk/lib/third_party/urllib3/util/ssl_.py", line 454, in ssl_wrap_socket
    ssl_sock = _ssl_wrap_socket_impl(
               ^^^^^^^^^^^^^^^^^^^^^^
  File "/Users/shashidharreddyneelam/Library/Application Support/cloud-code/installer/google-cloud-sdk/lib/third_party/urllib3/util/ssl_.py", line 498, in _ssl_wrap_socket_impl
    return ssl_context.wrap_socket(sock, server_hostname=server_hostname)
           ^^^^^^^^^^^^^^^^^^^^^^^^^^^^^^^^^^^^^^^^^^^^^^^^^^^^^^^^^^^^^^
  File "/Library/Frameworks/Python.framework/Versions/3.11/lib/python3.11/ssl.py", line 517, in wrap_socket
    return self.sslsocket_class._create(
           ^^^^^^^^^^^^^^^^^^^^^^^^^^^^^
  File "/Library/Frameworks/Python.framework/Versions/3.11/lib/python3.11/ssl.py", line 1075, in _create
    self.do_handshake()
  File "/Library/Frameworks/Python.framework/Versions/3.11/lib/python3.11/ssl.py", line 1346, in do_handshake
    self._sslobj.do_handshake()
ConnectionResetError: [Errno 54] Connection reset by peer

During handling of the above exception, another exception occurred:

Traceback (most recent call last):
  File "/Users/shashidharreddyneelam/Library/Application Support/cloud-code/installer/google-cloud-sdk/lib/third_party/requests/adapters.py", line 439, in send
    resp = conn.urlopen(
           ^^^^^^^^^^^^^
  File "/Users/shashidharreddyneelam/Library/Application Support/cloud-code/installer/google-cloud-sdk/lib/third_party/urllib3/connectionpool.py", line 785, in urlopen
    retries = retries.increment(
              ^^^^^^^^^^^^^^^^^^
  File "/Users/shashidharreddyneelam/Library/Application Support/cloud-code/installer/google-cloud-sdk/lib/third_party/urllib3/util/retry.py", line 550, in increment
    raise six.reraise(type(error), error, _stacktrace)
          ^^^^^^^^^^^^^^^^^^^^^^^^^^^^^^^^^^^^^^^^^^^^
  File "/Users/shashidharreddyneelam/Library/Application Support/cloud-code/installer/google-cloud-sdk/lib/third_party/urllib3/packages/six.py", line 769, in reraise
    raise value.with_traceback(tb)
  File "/Users/shashidharreddyneelam/Library/Application Support/cloud-code/installer/google-cloud-sdk/lib/third_party/urllib3/connectionpool.py", line 703, in urlopen
    httplib_response = self._make_request(
                       ^^^^^^^^^^^^^^^^^^^
  File "/Users/shashidharreddyneelam/Library/Application Support/cloud-code/installer/google-cloud-sdk/lib/third_party/urllib3/connectionpool.py", line 386, in _make_request
    self._validate_conn(conn)
  File "/Users/shashidharreddyneelam/Library/Application Support/cloud-code/installer/google-cloud-sdk/lib/third_party/urllib3/connectionpool.py", line 1040, in _validate_conn
    conn.connect()
  File "/Users/shashidharreddyneelam/Library/Application Support/cloud-code/installer/google-cloud-sdk/lib/third_party/urllib3/connection.py", line 414, in connect
    self.sock = ssl_wrap_socket(
                ^^^^^^^^^^^^^^^^
  File "/Users/shashidharreddyneelam/Library/Application Support/cloud-code/installer/google-cloud-sdk/lib/third_party/urllib3/util/ssl_.py", line 454, in ssl_wrap_socket
    ssl_sock = _ssl_wrap_socket_impl(
               ^^^^^^^^^^^^^^^^^^^^^^
  File "/Users/shashidharreddyneelam/Library/Application Support/cloud-code/installer/google-cloud-sdk/lib/third_party/urllib3/util/ssl_.py", line 498, in _ssl_wrap_socket_impl
    return ssl_context.wrap_socket(sock, server_hostname=server_hostname)
           ^^^^^^^^^^^^^^^^^^^^^^^^^^^^^^^^^^^^^^^^^^^^^^^^^^^^^^^^^^^^^^
  File "/Library/Frameworks/Python.framework/Versions/3.11/lib/python3.11/ssl.py", line 517, in wrap_socket
    return self.sslsocket_class._create(
           ^^^^^^^^^^^^^^^^^^^^^^^^^^^^^
  File "/Library/Frameworks/Python.framework/Versions/3.11/lib/python3.11/ssl.py", line 1075, in _create
    self.do_handshake()
  File "/Library/Frameworks/Python.framework/Versions/3.11/lib/python3.11/ssl.py", line 1346, in do_handshake
    self._sslobj.do_handshake()
urllib3.exceptions.ProtocolError: ('Connection aborted.', ConnectionResetError(54, 'Connection reset by peer'))

During handling of the above exception, another exception occurred:

Traceback (most recent call last):
  File "/Users/shashidharreddyneelam/Library/Application Support/cloud-code/installer/google-cloud-sdk/lib/googlecloudsdk/gcloud_main.py", line 61, in UpdateCheck
    update_manager.UpdateManager.PerformUpdateCheck(command_path=command_path)
  File "/Users/shashidharreddyneelam/Library/Application Support/cloud-code/installer/google-cloud-sdk/lib/googlecloudsdk/core/updater/update_manager.py", line 304, in PerformUpdateCheck
    manager._PerformUpdateCheck(command_path, force=force)
  File "/Users/shashidharreddyneelam/Library/Application Support/cloud-code/installer/google-cloud-sdk/lib/googlecloudsdk/core/updater/update_manager.py", line 738, in _PerformUpdateCheck
    (_, diff) = self._GetStateAndDiff(
                ^^^^^^^^^^^^^^^^^^^^^^
  File "/Users/shashidharreddyneelam/Library/Application Support/cloud-code/installer/google-cloud-sdk/lib/googlecloudsdk/core/updater/update_manager.py", line 692, in _GetStateAndDiff
    latest_snapshot = self._GetLatestSnapshot(version=version,
                      ^^^^^^^^^^^^^^^^^^^^^^^^^^^^^^^^^^^^^^^^
  File "/Users/shashidharreddyneelam/Library/Application Support/cloud-code/installer/google-cloud-sdk/lib/googlecloudsdk/core/updater/update_manager.py", line 675, in _GetLatestSnapshot
    return snapshots.ComponentSnapshot.FromURLs(
           ^^^^^^^^^^^^^^^^^^^^^^^^^^^^^^^^^^^^^
  File "/Users/shashidharreddyneelam/Library/Application Support/cloud-code/installer/google-cloud-sdk/lib/googlecloudsdk/core/updater/snapshots.py", line 175, in FromURLs
    data = [
           ^
  File "/Users/shashidharreddyneelam/Library/Application Support/cloud-code/installer/google-cloud-sdk/lib/googlecloudsdk/core/updater/snapshots.py", line 176, in <listcomp>
    (ComponentSnapshot._DictFromURL(
     ^^^^^^^^^^^^^^^^^^^^^^^^^^^^^^^
  File "/Users/shashidharreddyneelam/Library/Application Support/cloud-code/installer/google-cloud-sdk/lib/googlecloudsdk/core/updater/snapshots.py", line 200, in _DictFromURL
    response = installers.MakeRequest(url, command_path)
               ^^^^^^^^^^^^^^^^^^^^^^^^^^^^^^^^^^^^^^^^^
  File "/Users/shashidharreddyneelam/Library/Application Support/cloud-code/installer/google-cloud-sdk/lib/googlecloudsdk/core/updater/installers.py", line 114, in MakeRequest
    return _RawRequest(url, headers=headers, timeout=timeout)
           ^^^^^^^^^^^^^^^^^^^^^^^^^^^^^^^^^^^^^^^^^^^^^^^^^^
  File "/Users/shashidharreddyneelam/Library/Application Support/cloud-code/installer/google-cloud-sdk/lib/googlecloudsdk/core/updater/installers.py", line 162, in _RawRequest
    return retryer.RetryOnException(
           ^^^^^^^^^^^^^^^^^^^^^^^^^
  File "/Users/shashidharreddyneelam/Library/Application Support/cloud-code/installer/google-cloud-sdk/lib/googlecloudsdk/core/util/retry.py", line 201, in RetryOnException
    exceptions.reraise(exc_info[1], tb=exc_info[2])
  File "/Users/shashidharreddyneelam/Library/Application Support/cloud-code/installer/google-cloud-sdk/lib/googlecloudsdk/core/exceptions.py", line 146, in reraise
    six.reraise(type(exc_value), exc_value, tb)
  File "/Users/shashidharreddyneelam/Library/Application Support/cloud-code/installer/google-cloud-sdk/lib/third_party/six/__init__.py", line 719, in reraise
    raise value
  File "/Users/shashidharreddyneelam/Library/Application Support/cloud-code/installer/google-cloud-sdk/lib/googlecloudsdk/core/util/retry.py", line 182, in TryFunc
    return func(*args, **kwargs), None
           ^^^^^^^^^^^^^^^^^^^^^
  File "/Users/shashidharreddyneelam/Library/Application Support/cloud-code/installer/google-cloud-sdk/lib/googlecloudsdk/core/updater/installers.py", line 192, in _ExecuteRequestAndRaiseExceptions
    response = requests_session.get(
               ^^^^^^^^^^^^^^^^^^^^^
  File "/Users/shashidharreddyneelam/Library/Application Support/cloud-code/installer/google-cloud-sdk/lib/third_party/requests/sessions.py", line 555, in get
    return self.request('GET', url, **kwargs)
           ^^^^^^^^^^^^^^^^^^^^^^^^^^^^^^^^^^
  File "/Users/shashidharreddyneelam/Library/Application Support/cloud-code/installer/google-cloud-sdk/lib/googlecloudsdk/core/transport.py", line 260, in WrappedRequest
    response = orig_request(*modified_args, **modified_kwargs)
               ^^^^^^^^^^^^^^^^^^^^^^^^^^^^^^^^^^^^^^^^^^^^^^^
  File "/Users/shashidharreddyneelam/Library/Application Support/cloud-code/installer/google-cloud-sdk/lib/googlecloudsdk/core/requests.py", line 246, in WrappedRequest
    return orig_request_method(*args, **kwargs)
           ^^^^^^^^^^^^^^^^^^^^^^^^^^^^^^^^^^^^
  File "/Users/shashidharreddyneelam/Library/Application Support/cloud-code/installer/google-cloud-sdk/lib/third_party/requests/sessions.py", line 542, in request
    resp = self.send(prep, **send_kwargs)
           ^^^^^^^^^^^^^^^^^^^^^^^^^^^^^^
  File "/Users/shashidharreddyneelam/Library/Application Support/cloud-code/installer/google-cloud-sdk/lib/third_party/requests/sessions.py", line 655, in send
    r = adapter.send(request, **kwargs)
        ^^^^^^^^^^^^^^^^^^^^^^^^^^^^^^^
  File "/Users/shashidharreddyneelam/Library/Application Support/cloud-code/installer/google-cloud-sdk/lib/third_party/requests/adapters.py", line 498, in send
    raise ConnectionError(err, request=request)
requests.exceptions.ConnectionError: ('Connection aborted.', ConnectionResetError(54, 'Connection reset by peer'))
2023-02-27 06:43:20,878 DEBUG    root            Failed to perform update check.
Traceback (most recent call last):
  File "/Users/shashidharreddyneelam/Library/Application Support/cloud-code/installer/google-cloud-sdk/lib/third_party/urllib3/connectionpool.py", line 703, in urlopen
    httplib_response = self._make_request(
                       ^^^^^^^^^^^^^^^^^^^
  File "/Users/shashidharreddyneelam/Library/Application Support/cloud-code/installer/google-cloud-sdk/lib/third_party/urllib3/connectionpool.py", line 386, in _make_request
    self._validate_conn(conn)
  File "/Users/shashidharreddyneelam/Library/Application Support/cloud-code/installer/google-cloud-sdk/lib/third_party/urllib3/connectionpool.py", line 1040, in _validate_conn
    conn.connect()
  File "/Users/shashidharreddyneelam/Library/Application Support/cloud-code/installer/google-cloud-sdk/lib/third_party/urllib3/connection.py", line 414, in connect
    self.sock = ssl_wrap_socket(
                ^^^^^^^^^^^^^^^^
  File "/Users/shashidharreddyneelam/Library/Application Support/cloud-code/installer/google-cloud-sdk/lib/third_party/urllib3/util/ssl_.py", line 454, in ssl_wrap_socket
    ssl_sock = _ssl_wrap_socket_impl(
               ^^^^^^^^^^^^^^^^^^^^^^
  File "/Users/shashidharreddyneelam/Library/Application Support/cloud-code/installer/google-cloud-sdk/lib/third_party/urllib3/util/ssl_.py", line 498, in _ssl_wrap_socket_impl
    return ssl_context.wrap_socket(sock, server_hostname=server_hostname)
           ^^^^^^^^^^^^^^^^^^^^^^^^^^^^^^^^^^^^^^^^^^^^^^^^^^^^^^^^^^^^^^
  File "/Library/Frameworks/Python.framework/Versions/3.11/lib/python3.11/ssl.py", line 517, in wrap_socket
    return self.sslsocket_class._create(
           ^^^^^^^^^^^^^^^^^^^^^^^^^^^^^
  File "/Library/Frameworks/Python.framework/Versions/3.11/lib/python3.11/ssl.py", line 1075, in _create
    self.do_handshake()
  File "/Library/Frameworks/Python.framework/Versions/3.11/lib/python3.11/ssl.py", line 1346, in do_handshake
    self._sslobj.do_handshake()
ConnectionResetError: [Errno 54] Connection reset by peer

During handling of the above exception, another exception occurred:

Traceback (most recent call last):
  File "/Users/shashidharreddyneelam/Library/Application Support/cloud-code/installer/google-cloud-sdk/lib/third_party/requests/adapters.py", line 439, in send
    resp = conn.urlopen(
           ^^^^^^^^^^^^^
  File "/Users/shashidharreddyneelam/Library/Application Support/cloud-code/installer/google-cloud-sdk/lib/third_party/urllib3/connectionpool.py", line 785, in urlopen
    retries = retries.increment(
              ^^^^^^^^^^^^^^^^^^
  File "/Users/shashidharreddyneelam/Library/Application Support/cloud-code/installer/google-cloud-sdk/lib/third_party/urllib3/util/retry.py", line 550, in increment
    raise six.reraise(type(error), error, _stacktrace)
          ^^^^^^^^^^^^^^^^^^^^^^^^^^^^^^^^^^^^^^^^^^^^
  File "/Users/shashidharreddyneelam/Library/Application Support/cloud-code/installer/google-cloud-sdk/lib/third_party/urllib3/packages/six.py", line 769, in reraise
    raise value.with_traceback(tb)
  File "/Users/shashidharreddyneelam/Library/Application Support/cloud-code/installer/google-cloud-sdk/lib/third_party/urllib3/connectionpool.py", line 703, in urlopen
    httplib_response = self._make_request(
                       ^^^^^^^^^^^^^^^^^^^
  File "/Users/shashidharreddyneelam/Library/Application Support/cloud-code/installer/google-cloud-sdk/lib/third_party/urllib3/connectionpool.py", line 386, in _make_request
    self._validate_conn(conn)
  File "/Users/shashidharreddyneelam/Library/Application Support/cloud-code/installer/google-cloud-sdk/lib/third_party/urllib3/connectionpool.py", line 1040, in _validate_conn
    conn.connect()
  File "/Users/shashidharreddyneelam/Library/Application Support/cloud-code/installer/google-cloud-sdk/lib/third_party/urllib3/connection.py", line 414, in connect
    self.sock = ssl_wrap_socket(
                ^^^^^^^^^^^^^^^^
  File "/Users/shashidharreddyneelam/Library/Application Support/cloud-code/installer/google-cloud-sdk/lib/third_party/urllib3/util/ssl_.py", line 454, in ssl_wrap_socket
    ssl_sock = _ssl_wrap_socket_impl(
               ^^^^^^^^^^^^^^^^^^^^^^
  File "/Users/shashidharreddyneelam/Library/Application Support/cloud-code/installer/google-cloud-sdk/lib/third_party/urllib3/util/ssl_.py", line 498, in _ssl_wrap_socket_impl
    return ssl_context.wrap_socket(sock, server_hostname=server_hostname)
           ^^^^^^^^^^^^^^^^^^^^^^^^^^^^^^^^^^^^^^^^^^^^^^^^^^^^^^^^^^^^^^
  File "/Library/Frameworks/Python.framework/Versions/3.11/lib/python3.11/ssl.py", line 517, in wrap_socket
    return self.sslsocket_class._create(
           ^^^^^^^^^^^^^^^^^^^^^^^^^^^^^
  File "/Library/Frameworks/Python.framework/Versions/3.11/lib/python3.11/ssl.py", line 1075, in _create
    self.do_handshake()
  File "/Library/Frameworks/Python.framework/Versions/3.11/lib/python3.11/ssl.py", line 1346, in do_handshake
    self._sslobj.do_handshake()
urllib3.exceptions.ProtocolError: ('Connection aborted.', ConnectionResetError(54, 'Connection reset by peer'))

During handling of the above exception, another exception occurred:

Traceback (most recent call last):
  File "/Users/shashidharreddyneelam/Library/Application Support/cloud-code/installer/google-cloud-sdk/lib/googlecloudsdk/gcloud_main.py", line 61, in UpdateCheck
    update_manager.UpdateManager.PerformUpdateCheck(command_path=command_path)
  File "/Users/shashidharreddyneelam/Library/Application Support/cloud-code/installer/google-cloud-sdk/lib/googlecloudsdk/core/updater/update_manager.py", line 304, in PerformUpdateCheck
    manager._PerformUpdateCheck(command_path, force=force)
  File "/Users/shashidharreddyneelam/Library/Application Support/cloud-code/installer/google-cloud-sdk/lib/googlecloudsdk/core/updater/update_manager.py", line 738, in _PerformUpdateCheck
    (_, diff) = self._GetStateAndDiff(
                ^^^^^^^^^^^^^^^^^^^^^^
  File "/Users/shashidharreddyneelam/Library/Application Support/cloud-code/installer/google-cloud-sdk/lib/googlecloudsdk/core/updater/update_manager.py", line 692, in _GetStateAndDiff
    latest_snapshot = self._GetLatestSnapshot(version=version,
                      ^^^^^^^^^^^^^^^^^^^^^^^^^^^^^^^^^^^^^^^^
  File "/Users/shashidharreddyneelam/Library/Application Support/cloud-code/installer/google-cloud-sdk/lib/googlecloudsdk/core/updater/update_manager.py", line 675, in _GetLatestSnapshot
    return snapshots.ComponentSnapshot.FromURLs(
           ^^^^^^^^^^^^^^^^^^^^^^^^^^^^^^^^^^^^^
  File "/Users/shashidharreddyneelam/Library/Application Support/cloud-code/installer/google-cloud-sdk/lib/googlecloudsdk/core/updater/snapshots.py", line 175, in FromURLs
    data = [
           ^
  File "/Users/shashidharreddyneelam/Library/Application Support/cloud-code/installer/google-cloud-sdk/lib/googlecloudsdk/core/updater/snapshots.py", line 176, in <listcomp>
    (ComponentSnapshot._DictFromURL(
     ^^^^^^^^^^^^^^^^^^^^^^^^^^^^^^^
  File "/Users/shashidharreddyneelam/Library/Application Support/cloud-code/installer/google-cloud-sdk/lib/googlecloudsdk/core/updater/snapshots.py", line 200, in _DictFromURL
    response = installers.MakeRequest(url, command_path)
               ^^^^^^^^^^^^^^^^^^^^^^^^^^^^^^^^^^^^^^^^^
  File "/Users/shashidharreddyneelam/Library/Application Support/cloud-code/installer/google-cloud-sdk/lib/googlecloudsdk/core/updater/installers.py", line 114, in MakeRequest
    return _RawRequest(url, headers=headers, timeout=timeout)
           ^^^^^^^^^^^^^^^^^^^^^^^^^^^^^^^^^^^^^^^^^^^^^^^^^^
  File "/Users/shashidharreddyneelam/Library/Application Support/cloud-code/installer/google-cloud-sdk/lib/googlecloudsdk/core/updater/installers.py", line 162, in _RawRequest
    return retryer.RetryOnException(
           ^^^^^^^^^^^^^^^^^^^^^^^^^
  File "/Users/shashidharreddyneelam/Library/Application Support/cloud-code/installer/google-cloud-sdk/lib/googlecloudsdk/core/util/retry.py", line 201, in RetryOnException
    exceptions.reraise(exc_info[1], tb=exc_info[2])
  File "/Users/shashidharreddyneelam/Library/Application Support/cloud-code/installer/google-cloud-sdk/lib/googlecloudsdk/core/exceptions.py", line 146, in reraise
    six.reraise(type(exc_value), exc_value, tb)
  File "/Users/shashidharreddyneelam/Library/Application Support/cloud-code/installer/google-cloud-sdk/lib/third_party/six/__init__.py", line 719, in reraise
    raise value
  File "/Users/shashidharreddyneelam/Library/Application Support/cloud-code/installer/google-cloud-sdk/lib/googlecloudsdk/core/util/retry.py", line 182, in TryFunc
    return func(*args, **kwargs), None
           ^^^^^^^^^^^^^^^^^^^^^
  File "/Users/shashidharreddyneelam/Library/Application Support/cloud-code/installer/google-cloud-sdk/lib/googlecloudsdk/core/updater/installers.py", line 192, in _ExecuteRequestAndRaiseExceptions
    response = requests_session.get(
               ^^^^^^^^^^^^^^^^^^^^^
  File "/Users/shashidharreddyneelam/Library/Application Support/cloud-code/installer/google-cloud-sdk/lib/third_party/requests/sessions.py", line 555, in get
    return self.request('GET', url, **kwargs)
           ^^^^^^^^^^^^^^^^^^^^^^^^^^^^^^^^^^
  File "/Users/shashidharreddyneelam/Library/Application Support/cloud-code/installer/google-cloud-sdk/lib/googlecloudsdk/core/transport.py", line 260, in WrappedRequest
    response = orig_request(*modified_args, **modified_kwargs)
               ^^^^^^^^^^^^^^^^^^^^^^^^^^^^^^^^^^^^^^^^^^^^^^^
  File "/Users/shashidharreddyneelam/Library/Application Support/cloud-code/installer/google-cloud-sdk/lib/googlecloudsdk/core/requests.py", line 246, in WrappedRequest
    return orig_request_method(*args, **kwargs)
           ^^^^^^^^^^^^^^^^^^^^^^^^^^^^^^^^^^^^
  File "/Users/shashidharreddyneelam/Library/Application Support/cloud-code/installer/google-cloud-sdk/lib/third_party/requests/sessions.py", line 542, in request
    resp = self.send(prep, **send_kwargs)
           ^^^^^^^^^^^^^^^^^^^^^^^^^^^^^^
  File "/Users/shashidharreddyneelam/Library/Application Support/cloud-code/installer/google-cloud-sdk/lib/third_party/requests/sessions.py", line 655, in send
    r = adapter.send(request, **kwargs)
        ^^^^^^^^^^^^^^^^^^^^^^^^^^^^^^^
  File "/Users/shashidharreddyneelam/Library/Application Support/cloud-code/installer/google-cloud-sdk/lib/third_party/requests/adapters.py", line 498, in send
    raise ConnectionError(err, request=request)
requests.exceptions.ConnectionError: ('Connection aborted.', ConnectionResetError(54, 'Connection reset by peer'))
